OperationalError at /dashboard/learner/
no such table: learning_sessions_booking
Request Method:	GET
Request URL:	http://3e4c4c4a-b60b-4556-9647-2c6022f13499-00-186qnvr9j3jvh.worf.replit.dev/dashboard/learner/
Django Version:	5.2.1
Exception Type:	OperationalError
Exception Value:	
no such table: learning_sessions_booking
Exception Location:	/home/runner/workspace/.pythonlibs/lib/python3.11/site-packages/django/db/backends/sqlite3/base.py, line 360, in execute
Raised during:	users.views.learner_dashboard
Python Executable:	/home/runner/workspace/.pythonlibs/bin/python
Python Version:	3.11.10
Python Path:	
['/home/runner/workspace',
 '/nix/store/lc7qv2ldzrs1aq3hbyzmbgvn0h2w26pl-sitecustomize/lib/python/site-packages',
 '/nix/store/dfg63lldbvcj207iyr9z0xw21d8ax02n-python3.11-pip-24.0/lib/python3.11/site-packages',
 '/nix/store/clx0mcir7qw8zk36zbr4jra789g3knf6-python3-3.11.10/lib/python311.zip',
 '/nix/store/clx0mcir7qw8zk36zbr4jra789g3knf6-python3-3.11.10/lib/python3.11',
 '/nix/store/clx0mcir7qw8zk36zbr4jra789g3knf6-python3-3.11.10/lib/python3.11/lib-dynload',
 '/home/runner/workspace/.pythonlibs/lib/python3.11/site-packages',
 '/home/runner/workspace/.pythonlibs/lib/python3.11/site-packages',
 '/nix/store/wblvmd5y7izx0z10d1w7ga7zc4apjxmb-python3.11-setuptools-75.1.1/lib/python3.11/site-packages']
Server time:	Sat, 24 May 2025 11:18:08 +0000
Traceback Switch to copy-and-paste view
/home/runner/workspace/.pythonlibs/lib/python3.11/site-packages/django/db/backends/utils.py, line 105, in _execute
                return self.cursor.execute(sql, params)
                            ^^^^^^^^^^^^^^^^^^^^^^^^^^^^^^^^ …
Local vars
/home/runner/workspace/.pythonlibs/lib/python3.11/site-packages/django/db/backends/sqlite3/base.py, line 360, in execute
        return super().execute(query, params)
                    ^^^^^^^^^^^^^^^^^^^^^^^^^^^^^^ …
Local vars
The above exception (no such table: learning_sessions_booking) was the direct cause of the following exception:
/home/runner/workspace/.pythonlibs/lib/python3.11/site-packages/django/core/handlers/exception.py, line 42, in inner
                response = await get_response(request)
                               ^^^^^^^^^^^^^^^^^^^^^^^^^^^ …
Local vars
/home/runner/workspace/.pythonlibs/lib/python3.11/site-packages/django/core/handlers/base.py, line 253, in _get_response_async
                response = await wrapped_callback(
                                 …
Local vars
/nix/store/clx0mcir7qw8zk36zbr4jra789g3knf6-python3-3.11.10/lib/python3.11/concurrent/futures/thread.py, line 58, in run
            result = self.fn(*self.args, **self.kwargs)
                       